An error occurred while calling the function `sv_simulate` with the arguments `args=()` and `kwargs={'bb_code_parameter': (18, 4), 'constraints': <codes_constructions.circuit_models.SeqOperationConstraints object at 0x7f0ff7354f50>, 'num_repetitions': 1}`.
concurrent.futures.process._RemoteTraceback: 
"""
Traceback (most recent call last):
  File "/home/lucas.slattery/micromamba/envs/system_performance/lib/python3.12/concurrent/futures/process.py", line 264, in _process_worker
    r = call_item.fn(*call_item.args, **call_item.kwargs)
        ^^^^^^^^^^^^^^^^^^^^^^^^^^^^^^^^^^^^^^^^^^^^^^^^^
  File "/home/lucas.slattery/micromamba/envs/system_performance/lib/python3.12/site-packages/adaptive_scheduler/utils.py", line 1167, in __call__
    return deserialized_function(*args, **kwargs)
           ^^^^^^^^^^^^^^^^^^^^^^^^^^^^^^^^^^^^^^
  File "/home/lucas.slattery/micromamba/envs/system_performance/lib/python3.12/site-packages/adaptive/learner/sequence_learner.py", line 53, in __call__
    return self.function(point, *args, **kwargs)
           ^^^^^^^^^^^^^^^^^^^^^^^^^^^^^^^^^^^^^
  File "/home/lucas.slattery/micromamba/envs/system_performance/lib/python3.12/site-packages/adaptive_scheduler/_executor.py", line 225, in __call__
    return self.func(*args)
           ^^^^^^^^^^^^^^^^
  File "/home/lucas.slattery/micromamba/envs/system_performance/lib/python3.12/site-packages/pipefunc/map/_run.py", line 817, in _process_chunk
    return list(map(process_index, chunk))
           ^^^^^^^^^^^^^^^^^^^^^^^^^^^^^^^
  File "/home/lucas.slattery/micromamba/envs/system_performance/lib/python3.12/site-packages/pipefunc/map/_run.py", line 567, in _run_iteration_and_process
    output = _run_iteration(func, selected, cache)
             ^^^^^^^^^^^^^^^^^^^^^^^^^^^^^^^^^^^^^
  File "/home/lucas.slattery/micromamba/envs/system_performance/lib/python3.12/site-packages/pipefunc/map/_run.py", line 534, in _run_iteration
    return _get_or_set_cache(func, selected, cache, compute_fn)
           ^^^^^^^^^^^^^^^^^^^^^^^^^^^^^^^^^^^^^^^^^^^^^^^^^^^^
  File "/home/lucas.slattery/micromamba/envs/system_performance/lib/python3.12/site-packages/pipefunc/map/_run.py", line 507, in _get_or_set_cache
    return compute_fn()
           ^^^^^^^^^^^^
  File "/home/lucas.slattery/micromamba/envs/system_performance/lib/python3.12/site-packages/pipefunc/map/_run.py", line 530, in compute_fn
    handle_error(e, func, selected)
  File "/home/lucas.slattery/micromamba/envs/system_performance/lib/python3.12/site-packages/pipefunc/map/_run.py", line 528, in compute_fn
    return func(**selected)
           ^^^^^^^^^^^^^^^^
  File "/home/lucas.slattery/micromamba/envs/system_performance/lib/python3.12/site-packages/pipefunc/_pipefunc.py", line 700, in __call__
    result = self.func(*args, **kwargs)
             ^^^^^^^^^^^^^^^^^^^^^^^^^^
  File "/home/lucas.slattery/clean_repo/qec_simulations/qec/benchmark_performance.py", line 107, in sv_simulate
    if cirq_circuit.num_qubits() > 36:
       ^^^^^^^^^^^^^^^^^^^^^^^
AttributeError: 'Circuit' object has no attribute 'num_qubits'. Did you mean: 'all_qubits'?
Error occurred while executing function `sv_simulate(bb_code_parameter=(18, 4), constraints=<codes_constructions.circuit_models.SeqOperationConstraints object at 0x7f0ff7354f50>, num_repetitions=1)`.
"""

The above exception was the direct cause of the following exception:

Traceback (most recent call last):
  File "/home/lucas.slattery/micromamba/envs/system_performance/lib/python3.12/site-packages/adaptive/runner.py", line 294, in _process_futures
    y = fut.result()
        ^^^^^^^^^^^^
AttributeError: 'Circuit' object has no attribute 'num_qubits'
Error occurred while executing function `sv_simulate(bb_code_parameter=(18, 4), constraints=<codes_constructions.circuit_models.SeqOperationConstraints object at 0x7f0ff7354f50>, num_repetitions=1)`.

The above exception was the direct cause of the following exception:

Traceback (most recent call last):
  File "/home/lucas.slattery/micromamba/envs/system_performance/lib/python3.12/site-packages/adaptive_scheduler/_server_support/launcher.py", line 185, in <module>
    main()
  File "/home/lucas.slattery/micromamba/envs/system_performance/lib/python3.12/site-packages/adaptive_scheduler/_server_support/launcher.py", line 169, in main
    runner.ioloop.run_until_complete(runner.task)
  File "uvloop/loop.pyx", line 1518, in uvloop.loop.Loop.run_until_complete
RuntimeError: An error occured while evaluating "learner.function((0, ((0,),)))". See the traceback for details.:

concurrent.futures.process._RemoteTraceback: 
"""
Traceback (most recent call last):
  File "/home/lucas.slattery/micromamba/envs/system_performance/lib/python3.12/concurrent/futures/process.py", line 264, in _process_worker
    r = call_item.fn(*call_item.args, **call_item.kwargs)
        ^^^^^^^^^^^^^^^^^^^^^^^^^^^^^^^^^^^^^^^^^^^^^^^^^
  File "/home/lucas.slattery/micromamba/envs/system_performance/lib/python3.12/site-packages/adaptive_scheduler/utils.py", line 1167, in __call__
    return deserialized_function(*args, **kwargs)
           ^^^^^^^^^^^^^^^^^^^^^^^^^^^^^^^^^^^^^^
  File "/home/lucas.slattery/micromamba/envs/system_performance/lib/python3.12/site-packages/adaptive/learner/sequence_learner.py", line 53, in __call__
    return self.function(point, *args, **kwargs)
           ^^^^^^^^^^^^^^^^^^^^^^^^^^^^^^^^^^^^^
  File "/home/lucas.slattery/micromamba/envs/system_performance/lib/python3.12/site-packages/adaptive_scheduler/_executor.py", line 225, in __call__
    return self.func(*args)
           ^^^^^^^^^^^^^^^^
  File "/home/lucas.slattery/micromamba/envs/system_performance/lib/python3.12/site-packages/pipefunc/map/_run.py", line 817, in _process_chunk
    return list(map(process_index, chunk))
           ^^^^^^^^^^^^^^^^^^^^^^^^^^^^^^^
  File "/home/lucas.slattery/micromamba/envs/system_performance/lib/python3.12/site-packages/pipefunc/map/_run.py", line 567, in _run_iteration_and_process
    output = _run_iteration(func, selected, cache)
             ^^^^^^^^^^^^^^^^^^^^^^^^^^^^^^^^^^^^^
  File "/home/lucas.slattery/micromamba/envs/system_performance/lib/python3.12/site-packages/pipefunc/map/_run.py", line 534, in _run_iteration
    return _get_or_set_cache(func, selected, cache, compute_fn)
           ^^^^^^^^^^^^^^^^^^^^^^^^^^^^^^^^^^^^^^^^^^^^^^^^^^^^
  File "/home/lucas.slattery/micromamba/envs/system_performance/lib/python3.12/site-packages/pipefunc/map/_run.py", line 507, in _get_or_set_cache
    return compute_fn()
           ^^^^^^^^^^^^
  File "/home/lucas.slattery/micromamba/envs/system_performance/lib/python3.12/site-packages/pipefunc/map/_run.py", line 530, in compute_fn
    handle_error(e, func, selected)
  File "/home/lucas.slattery/micromamba/envs/system_performance/lib/python3.12/site-packages/pipefunc/map/_run.py", line 528, in compute_fn
    return func(**selected)
           ^^^^^^^^^^^^^^^^
  File "/home/lucas.slattery/micromamba/envs/system_performance/lib/python3.12/site-packages/pipefunc/_pipefunc.py", line 700, in __call__
    result = self.func(*args, **kwargs)
             ^^^^^^^^^^^^^^^^^^^^^^^^^^
  File "/home/lucas.slattery/clean_repo/qec_simulations/qec/benchmark_performance.py", line 107, in sv_simulate
    if cirq_circuit.num_qubits() > 36:
       ^^^^^^^^^^^^^^^^^^^^^^^
AttributeError: 'Circuit' object has no attribute 'num_qubits'. Did you mean: 'all_qubits'?
Error occurred while executing function `sv_simulate(bb_code_parameter=(18, 4), constraints=<codes_constructions.circuit_models.SeqOperationConstraints object at 0x7f0ff7354f50>, num_repetitions=1)`.
"""

The above exception was the direct cause of the following exception:

Traceback (most recent call last):
  File "/home/lucas.slattery/micromamba/envs/system_performance/lib/python3.12/site-packages/adaptive/runner.py", line 294, in _process_futures
    y = fut.result()
        ^^^^^^^^^^^^
AttributeError: 'Circuit' object has no attribute 'num_qubits'
Error occurred while executing function `sv_simulate(bb_code_parameter=(18, 4), constraints=<codes_constructions.circuit_models.SeqOperationConstraints object at 0x7f0ff7354f50>, num_repetitions=1)`.

