An error occurred while calling the function `mps_simulate` with the arguments `args=()` and `kwargs={'bb_code_parameter': (18, 4), 'constraints': <codes_constructions.circuit_models.SeqOperationConstraints object at 0x750657dda900>, 'lazy_indexing': False, 'chi': 1, 'num_repetitions': 1}`.
concurrent.futures.process._RemoteTraceback: 
"""
Traceback (most recent call last):
  File "/home/lucas.slattery/micromamba/envs/system_performance/lib/python3.12/concurrent/futures/process.py", line 264, in _process_worker
    r = call_item.fn(*call_item.args, **call_item.kwargs)
        ^^^^^^^^^^^^^^^^^^^^^^^^^^^^^^^^^^^^^^^^^^^^^^^^^
  File "/home/lucas.slattery/micromamba/envs/system_performance/lib/python3.12/site-packages/adaptive_scheduler/utils.py", line 1167, in __call__
    return deserialized_function(*args, **kwargs)
           ^^^^^^^^^^^^^^^^^^^^^^^^^^^^^^^^^^^^^^
  File "/home/lucas.slattery/micromamba/envs/system_performance/lib/python3.12/site-packages/adaptive/learner/sequence_learner.py", line 53, in __call__
    return self.function(point, *args, **kwargs)
           ^^^^^^^^^^^^^^^^^^^^^^^^^^^^^^^^^^^^^
  File "/home/lucas.slattery/micromamba/envs/system_performance/lib/python3.12/site-packages/adaptive_scheduler/_executor.py", line 225, in __call__
    return self.func(*args)
           ^^^^^^^^^^^^^^^^
  File "/home/lucas.slattery/micromamba/envs/system_performance/lib/python3.12/site-packages/pipefunc/map/_run.py", line 817, in _process_chunk
    return list(map(process_index, chunk))
           ^^^^^^^^^^^^^^^^^^^^^^^^^^^^^^^
  File "/home/lucas.slattery/micromamba/envs/system_performance/lib/python3.12/site-packages/pipefunc/map/_run.py", line 567, in _run_iteration_and_process
    output = _run_iteration(func, selected, cache)
             ^^^^^^^^^^^^^^^^^^^^^^^^^^^^^^^^^^^^^
  File "/home/lucas.slattery/micromamba/envs/system_performance/lib/python3.12/site-packages/pipefunc/map/_run.py", line 534, in _run_iteration
    return _get_or_set_cache(func, selected, cache, compute_fn)
           ^^^^^^^^^^^^^^^^^^^^^^^^^^^^^^^^^^^^^^^^^^^^^^^^^^^^
  File "/home/lucas.slattery/micromamba/envs/system_performance/lib/python3.12/site-packages/pipefunc/map/_run.py", line 507, in _get_or_set_cache
    return compute_fn()
           ^^^^^^^^^^^^
  File "/home/lucas.slattery/micromamba/envs/system_performance/lib/python3.12/site-packages/pipefunc/map/_run.py", line 530, in compute_fn
    handle_error(e, func, selected)
  File "/home/lucas.slattery/micromamba/envs/system_performance/lib/python3.12/site-packages/pipefunc/map/_run.py", line 528, in compute_fn
    return func(**selected)
           ^^^^^^^^^^^^^^^^
  File "/home/lucas.slattery/micromamba/envs/system_performance/lib/python3.12/site-packages/pipefunc/_pipefunc.py", line 700, in __call__
    result = self.func(*args, **kwargs)
             ^^^^^^^^^^^^^^^^^^^^^^^^^^
  File "/home/lucas.slattery/clean_repo/qec_simulations/qec/benchmark_performance.py", line 51, in mps_simulate
    result = sim.simulate(circuit)
             ^^^^^^^^^^^^^^^^^^^^^
  File "/home/lucas.slattery/micromamba/envs/system_performance/lib/python3.12/site-packages/cirq/sim/simulator.py", line 496, in simulate
    return self.simulate_sweep(
           ^^^^^^^^^^^^^^^^^^^^
  File "/home/lucas.slattery/micromamba/envs/system_performance/lib/python3.12/site-packages/cirq/sim/simulator.py", line 511, in simulate_sweep
    return list(self.simulate_sweep_iter(program, params, qubit_order, initial_state))
           ^^^^^^^^^^^^^^^^^^^^^^^^^^^^^^^^^^^^^^^^^^^^^^^^^^^^^^^^^^^^^^^^^^^^^^^^^^^
  File "/home/lucas.slattery/micromamba/envs/system_performance/lib/python3.12/site-packages/cirq/sim/simulator_base.py", line 319, in simulate_sweep_iter
    qubits = ops.QubitOrder.as_qubit_order(qubit_order).order_for(program.all_qubits())
                                                                  ^^^^^^^^^^^^^^^^^^
AttributeError: 'stim._stim_sse2.Circuit' object has no attribute 'all_qubits'. Did you mean: 'num_qubits'?
Error occurred while executing function `mps_simulate(bb_code_parameter=(18, 4), constraints=<codes_constructions.circuit_models.SeqOperationConstraints object at 0x750657dda900>, lazy_indexing=False, chi=1, num_repetitions=1)`.
"""

The above exception was the direct cause of the following exception:

Traceback (most recent call last):
  File "/home/lucas.slattery/micromamba/envs/system_performance/lib/python3.12/site-packages/adaptive/runner.py", line 294, in _process_futures
    y = fut.result()
        ^^^^^^^^^^^^
AttributeError: 'stim._stim_sse2.Circuit' object has no attribute 'all_qubits'
Error occurred while executing function `mps_simulate(bb_code_parameter=(18, 4), constraints=<codes_constructions.circuit_models.SeqOperationConstraints object at 0x750657dda900>, lazy_indexing=False, chi=1, num_repetitions=1)`.

The above exception was the direct cause of the following exception:

Traceback (most recent call last):
  File "/home/lucas.slattery/micromamba/envs/system_performance/lib/python3.12/site-packages/adaptive_scheduler/_server_support/launcher.py", line 185, in <module>
    main()
  File "/home/lucas.slattery/micromamba/envs/system_performance/lib/python3.12/site-packages/adaptive_scheduler/_server_support/launcher.py", line 169, in main
    runner.ioloop.run_until_complete(runner.task)
  File "uvloop/loop.pyx", line 1518, in uvloop.loop.Loop.run_until_complete
RuntimeError: An error occured while evaluating "learner.function((0, ((0,),)))". See the traceback for details.:

concurrent.futures.process._RemoteTraceback: 
"""
Traceback (most recent call last):
  File "/home/lucas.slattery/micromamba/envs/system_performance/lib/python3.12/concurrent/futures/process.py", line 264, in _process_worker
    r = call_item.fn(*call_item.args, **call_item.kwargs)
        ^^^^^^^^^^^^^^^^^^^^^^^^^^^^^^^^^^^^^^^^^^^^^^^^^
  File "/home/lucas.slattery/micromamba/envs/system_performance/lib/python3.12/site-packages/adaptive_scheduler/utils.py", line 1167, in __call__
    return deserialized_function(*args, **kwargs)
           ^^^^^^^^^^^^^^^^^^^^^^^^^^^^^^^^^^^^^^
  File "/home/lucas.slattery/micromamba/envs/system_performance/lib/python3.12/site-packages/adaptive/learner/sequence_learner.py", line 53, in __call__
    return self.function(point, *args, **kwargs)
           ^^^^^^^^^^^^^^^^^^^^^^^^^^^^^^^^^^^^^
  File "/home/lucas.slattery/micromamba/envs/system_performance/lib/python3.12/site-packages/adaptive_scheduler/_executor.py", line 225, in __call__
    return self.func(*args)
           ^^^^^^^^^^^^^^^^
  File "/home/lucas.slattery/micromamba/envs/system_performance/lib/python3.12/site-packages/pipefunc/map/_run.py", line 817, in _process_chunk
    return list(map(process_index, chunk))
           ^^^^^^^^^^^^^^^^^^^^^^^^^^^^^^^
  File "/home/lucas.slattery/micromamba/envs/system_performance/lib/python3.12/site-packages/pipefunc/map/_run.py", line 567, in _run_iteration_and_process
    output = _run_iteration(func, selected, cache)
             ^^^^^^^^^^^^^^^^^^^^^^^^^^^^^^^^^^^^^
  File "/home/lucas.slattery/micromamba/envs/system_performance/lib/python3.12/site-packages/pipefunc/map/_run.py", line 534, in _run_iteration
    return _get_or_set_cache(func, selected, cache, compute_fn)
           ^^^^^^^^^^^^^^^^^^^^^^^^^^^^^^^^^^^^^^^^^^^^^^^^^^^^
  File "/home/lucas.slattery/micromamba/envs/system_performance/lib/python3.12/site-packages/pipefunc/map/_run.py", line 507, in _get_or_set_cache
    return compute_fn()
           ^^^^^^^^^^^^
  File "/home/lucas.slattery/micromamba/envs/system_performance/lib/python3.12/site-packages/pipefunc/map/_run.py", line 530, in compute_fn
    handle_error(e, func, selected)
  File "/home/lucas.slattery/micromamba/envs/system_performance/lib/python3.12/site-packages/pipefunc/map/_run.py", line 528, in compute_fn
    return func(**selected)
           ^^^^^^^^^^^^^^^^
  File "/home/lucas.slattery/micromamba/envs/system_performance/lib/python3.12/site-packages/pipefunc/_pipefunc.py", line 700, in __call__
    result = self.func(*args, **kwargs)
             ^^^^^^^^^^^^^^^^^^^^^^^^^^
  File "/home/lucas.slattery/clean_repo/qec_simulations/qec/benchmark_performance.py", line 51, in mps_simulate
    result = sim.simulate(circuit)
             ^^^^^^^^^^^^^^^^^^^^^
  File "/home/lucas.slattery/micromamba/envs/system_performance/lib/python3.12/site-packages/cirq/sim/simulator.py", line 496, in simulate
    return self.simulate_sweep(
           ^^^^^^^^^^^^^^^^^^^^
  File "/home/lucas.slattery/micromamba/envs/system_performance/lib/python3.12/site-packages/cirq/sim/simulator.py", line 511, in simulate_sweep
    return list(self.simulate_sweep_iter(program, params, qubit_order, initial_state))
           ^^^^^^^^^^^^^^^^^^^^^^^^^^^^^^^^^^^^^^^^^^^^^^^^^^^^^^^^^^^^^^^^^^^^^^^^^^^
  File "/home/lucas.slattery/micromamba/envs/system_performance/lib/python3.12/site-packages/cirq/sim/simulator_base.py", line 319, in simulate_sweep_iter
    qubits = ops.QubitOrder.as_qubit_order(qubit_order).order_for(program.all_qubits())
                                                                  ^^^^^^^^^^^^^^^^^^
AttributeError: 'stim._stim_sse2.Circuit' object has no attribute 'all_qubits'. Did you mean: 'num_qubits'?
Error occurred while executing function `mps_simulate(bb_code_parameter=(18, 4), constraints=<codes_constructions.circuit_models.SeqOperationConstraints object at 0x750657dda900>, lazy_indexing=False, chi=1, num_repetitions=1)`.
"""

The above exception was the direct cause of the following exception:

Traceback (most recent call last):
  File "/home/lucas.slattery/micromamba/envs/system_performance/lib/python3.12/site-packages/adaptive/runner.py", line 294, in _process_futures
    y = fut.result()
        ^^^^^^^^^^^^
AttributeError: 'stim._stim_sse2.Circuit' object has no attribute 'all_qubits'
Error occurred while executing function `mps_simulate(bb_code_parameter=(18, 4), constraints=<codes_constructions.circuit_models.SeqOperationConstraints object at 0x750657dda900>, lazy_indexing=False, chi=1, num_repetitions=1)`.

