/home/lucas.slattery/clean_repo/system_performance/qcircuitsim/ionq/qcircuitsim/backends/quimb/quimb_mps_results.py:386: ComplexWarning: Casting complex values to real discards the imaginary part
  [max(0, float(d_sv / norm)) for d_sv, norm in zip(discarded_sv_norms, norms, strict=False)]
/home/lucas.slattery/clean_repo/qec_simulations/qec/benchmark_performance.py:92: ComplexWarning: Casting complex values to real discards the imaginary part
  this_result["estimated_fidelity"] = float(result.final_state.estimation_stats()["estimated_fidelity"])
An error occurred while calling the function `mps_simulate` with the arguments `args=()` and `kwargs={'bb_code_parameter': (18, 4), 'constraints': <codes_constructions.circuit_models.SeqOperationConstraints object at 0x73dfd4bed6d0>, 'lazy_indexing': True, 'chi': 64, 'num_repetitions': 1}`.
concurrent.futures.process._RemoteTraceback: 
"""
Traceback (most recent call last):
  File "/home/lucas.slattery/micromamba/envs/system_performance/lib/python3.12/concurrent/futures/process.py", line 264, in _process_worker
    r = call_item.fn(*call_item.args, **call_item.kwargs)
        ^^^^^^^^^^^^^^^^^^^^^^^^^^^^^^^^^^^^^^^^^^^^^^^^^
  File "/home/lucas.slattery/micromamba/envs/system_performance/lib/python3.12/site-packages/adaptive_scheduler/utils.py", line 1167, in __call__
    return deserialized_function(*args, **kwargs)
           ^^^^^^^^^^^^^^^^^^^^^^^^^^^^^^^^^^^^^^
  File "/home/lucas.slattery/micromamba/envs/system_performance/lib/python3.12/site-packages/adaptive/learner/sequence_learner.py", line 53, in __call__
    return self.function(point, *args, **kwargs)
           ^^^^^^^^^^^^^^^^^^^^^^^^^^^^^^^^^^^^^
  File "/home/lucas.slattery/micromamba/envs/system_performance/lib/python3.12/site-packages/adaptive_scheduler/_executor.py", line 225, in __call__
    return self.func(*args)
           ^^^^^^^^^^^^^^^^
  File "/home/lucas.slattery/micromamba/envs/system_performance/lib/python3.12/site-packages/pipefunc/map/_run.py", line 817, in _process_chunk
    return list(map(process_index, chunk))
           ^^^^^^^^^^^^^^^^^^^^^^^^^^^^^^^
  File "/home/lucas.slattery/micromamba/envs/system_performance/lib/python3.12/site-packages/pipefunc/map/_run.py", line 567, in _run_iteration_and_process
    output = _run_iteration(func, selected, cache)
             ^^^^^^^^^^^^^^^^^^^^^^^^^^^^^^^^^^^^^
  File "/home/lucas.slattery/micromamba/envs/system_performance/lib/python3.12/site-packages/pipefunc/map/_run.py", line 534, in _run_iteration
    return _get_or_set_cache(func, selected, cache, compute_fn)
           ^^^^^^^^^^^^^^^^^^^^^^^^^^^^^^^^^^^^^^^^^^^^^^^^^^^^
  File "/home/lucas.slattery/micromamba/envs/system_performance/lib/python3.12/site-packages/pipefunc/map/_run.py", line 507, in _get_or_set_cache
    return compute_fn()
           ^^^^^^^^^^^^
  File "/home/lucas.slattery/micromamba/envs/system_performance/lib/python3.12/site-packages/pipefunc/map/_run.py", line 530, in compute_fn
    handle_error(e, func, selected)
  File "/home/lucas.slattery/micromamba/envs/system_performance/lib/python3.12/site-packages/pipefunc/map/_run.py", line 528, in compute_fn
    return func(**selected)
           ^^^^^^^^^^^^^^^^
  File "/home/lucas.slattery/micromamba/envs/system_performance/lib/python3.12/site-packages/pipefunc/_pipefunc.py", line 700, in __call__
    result = self.func(*args, **kwargs)
             ^^^^^^^^^^^^^^^^^^^^^^^^^^
  File "/home/lucas.slattery/clean_repo/qec_simulations/qec/benchmark_performance.py", line 96, in mps_simulate
    num_ancilla = constraints.num_ancilla
                  ^^^^^^^^^^^^^^^^^^^^^^^
AttributeError: 'SeqOperationConstraints' object has no attribute 'num_ancilla'. Did you mean: 'num_ancillas'?
Error occurred while executing function `mps_simulate(bb_code_parameter=(18, 4), constraints=<codes_constructions.circuit_models.SeqOperationConstraints object at 0x73dfd4bed6d0>, lazy_indexing=True, chi=64, num_repetitions=1)`.
"""

The above exception was the direct cause of the following exception:

Traceback (most recent call last):
  File "/home/lucas.slattery/micromamba/envs/system_performance/lib/python3.12/site-packages/adaptive/runner.py", line 294, in _process_futures
    y = fut.result()
        ^^^^^^^^^^^^
AttributeError: 'SeqOperationConstraints' object has no attribute 'num_ancilla'
Error occurred while executing function `mps_simulate(bb_code_parameter=(18, 4), constraints=<codes_constructions.circuit_models.SeqOperationConstraints object at 0x73dfd4bed6d0>, lazy_indexing=True, chi=64, num_repetitions=1)`.

The above exception was the direct cause of the following exception:

Traceback (most recent call last):
  File "/home/lucas.slattery/micromamba/envs/system_performance/lib/python3.12/site-packages/adaptive_scheduler/_server_support/launcher.py", line 185, in <module>
    main()
  File "/home/lucas.slattery/micromamba/envs/system_performance/lib/python3.12/site-packages/adaptive_scheduler/_server_support/launcher.py", line 169, in main
    runner.ioloop.run_until_complete(runner.task)
  File "uvloop/loop.pyx", line 1518, in uvloop.loop.Loop.run_until_complete
RuntimeError: An error occured while evaluating "learner.function((0, ((61,),)))". See the traceback for details.:

concurrent.futures.process._RemoteTraceback: 
"""
Traceback (most recent call last):
  File "/home/lucas.slattery/micromamba/envs/system_performance/lib/python3.12/concurrent/futures/process.py", line 264, in _process_worker
    r = call_item.fn(*call_item.args, **call_item.kwargs)
        ^^^^^^^^^^^^^^^^^^^^^^^^^^^^^^^^^^^^^^^^^^^^^^^^^
  File "/home/lucas.slattery/micromamba/envs/system_performance/lib/python3.12/site-packages/adaptive_scheduler/utils.py", line 1167, in __call__
    return deserialized_function(*args, **kwargs)
           ^^^^^^^^^^^^^^^^^^^^^^^^^^^^^^^^^^^^^^
  File "/home/lucas.slattery/micromamba/envs/system_performance/lib/python3.12/site-packages/adaptive/learner/sequence_learner.py", line 53, in __call__
    return self.function(point, *args, **kwargs)
           ^^^^^^^^^^^^^^^^^^^^^^^^^^^^^^^^^^^^^
  File "/home/lucas.slattery/micromamba/envs/system_performance/lib/python3.12/site-packages/adaptive_scheduler/_executor.py", line 225, in __call__
    return self.func(*args)
           ^^^^^^^^^^^^^^^^
  File "/home/lucas.slattery/micromamba/envs/system_performance/lib/python3.12/site-packages/pipefunc/map/_run.py", line 817, in _process_chunk
    return list(map(process_index, chunk))
           ^^^^^^^^^^^^^^^^^^^^^^^^^^^^^^^
  File "/home/lucas.slattery/micromamba/envs/system_performance/lib/python3.12/site-packages/pipefunc/map/_run.py", line 567, in _run_iteration_and_process
    output = _run_iteration(func, selected, cache)
             ^^^^^^^^^^^^^^^^^^^^^^^^^^^^^^^^^^^^^
  File "/home/lucas.slattery/micromamba/envs/system_performance/lib/python3.12/site-packages/pipefunc/map/_run.py", line 534, in _run_iteration
    return _get_or_set_cache(func, selected, cache, compute_fn)
           ^^^^^^^^^^^^^^^^^^^^^^^^^^^^^^^^^^^^^^^^^^^^^^^^^^^^
  File "/home/lucas.slattery/micromamba/envs/system_performance/lib/python3.12/site-packages/pipefunc/map/_run.py", line 507, in _get_or_set_cache
    return compute_fn()
           ^^^^^^^^^^^^
  File "/home/lucas.slattery/micromamba/envs/system_performance/lib/python3.12/site-packages/pipefunc/map/_run.py", line 530, in compute_fn
    handle_error(e, func, selected)
  File "/home/lucas.slattery/micromamba/envs/system_performance/lib/python3.12/site-packages/pipefunc/map/_run.py", line 528, in compute_fn
    return func(**selected)
           ^^^^^^^^^^^^^^^^
  File "/home/lucas.slattery/micromamba/envs/system_performance/lib/python3.12/site-packages/pipefunc/_pipefunc.py", line 700, in __call__
    result = self.func(*args, **kwargs)
             ^^^^^^^^^^^^^^^^^^^^^^^^^^
  File "/home/lucas.slattery/clean_repo/qec_simulations/qec/benchmark_performance.py", line 96, in mps_simulate
    num_ancilla = constraints.num_ancilla
                  ^^^^^^^^^^^^^^^^^^^^^^^
AttributeError: 'SeqOperationConstraints' object has no attribute 'num_ancilla'. Did you mean: 'num_ancillas'?
Error occurred while executing function `mps_simulate(bb_code_parameter=(18, 4), constraints=<codes_constructions.circuit_models.SeqOperationConstraints object at 0x73dfd4bed6d0>, lazy_indexing=True, chi=64, num_repetitions=1)`.
"""

The above exception was the direct cause of the following exception:

Traceback (most recent call last):
  File "/home/lucas.slattery/micromamba/envs/system_performance/lib/python3.12/site-packages/adaptive/runner.py", line 294, in _process_futures
    y = fut.result()
        ^^^^^^^^^^^^
AttributeError: 'SeqOperationConstraints' object has no attribute 'num_ancilla'
Error occurred while executing function `mps_simulate(bb_code_parameter=(18, 4), constraints=<codes_constructions.circuit_models.SeqOperationConstraints object at 0x73dfd4bed6d0>, lazy_indexing=True, chi=64, num_repetitions=1)`.

