/home/lucas.slattery/micromamba/envs/system_performance/lib/python3.12/site-packages/quimb/tensor/decomp.py:347: UserWarning: Got: Internal algorithm failed to converge., falling back to scipy gesvd driver.
  warnings.warn(f"Got: {e}, falling back to scipy gesvd driver.")
Traceback (most recent call last):
  File "/home/lucas.slattery/micromamba/envs/system_performance/lib/python3.12/site-packages/adaptive/runner.py", line 294, in _process_futures
    y = fut.result()
        ^^^^^^^^^^^^
concurrent.futures.process.BrokenProcessPool: A process in the process pool was terminated abruptly while the future was running or pending.

The above exception was the direct cause of the following exception:

Traceback (most recent call last):
  File "/home/lucas.slattery/micromamba/envs/system_performance/lib/python3.12/site-packages/adaptive_scheduler/_server_support/launcher.py", line 185, in <module>
    main()
  File "/home/lucas.slattery/micromamba/envs/system_performance/lib/python3.12/site-packages/adaptive_scheduler/_server_support/launcher.py", line 169, in main
    runner.ioloop.run_until_complete(runner.task)
  File "uvloop/loop.pyx", line 1518, in uvloop.loop.Loop.run_until_complete
RuntimeError: An error occured while evaluating "learner.function((0, ((252,),)))". See the traceback for details.:

Traceback (most recent call last):
  File "/home/lucas.slattery/micromamba/envs/system_performance/lib/python3.12/site-packages/adaptive/runner.py", line 294, in _process_futures
    y = fut.result()
        ^^^^^^^^^^^^
concurrent.futures.process.BrokenProcessPool: A process in the process pool was terminated abruptly while the future was running or pending.

slurmstepd-obsidian-5: error: Detected 1 oom_kill event in StepId=2599310.batch. Some of the step tasks have been OOM Killed.
